<?xml version="1.0" encoding="UTF-8"?>
<rss version="2.0">
  <channel>
    <title>OpenAI 开发者论坛 - 最新帖子</title>
    <link>https://community.openai.com</link>
    <description>最新帖子</description>
    <lastBuildDate>Sat, 30 Dec 2023 15:17:10 GMT</lastBuildDate>
    <item>
      <title>扩展ChatGPT的演绎和逻辑推理能力</title>
      <link>https://community.openai.com/t/extending-chatgpts-deductive-and-logical-reasoning-capabilities/569484?page=2#post_28</link>
      <description><![CDATA[@gmkung，我通读了这篇文章并想到了潜在的用例。业务系统分析是一个有潜力的领域。
我们可以将任何业务视为资源和具有步骤和任务的互连流程的集合。每个进程都有一个所需的输出，该输出消耗其他进程的输入。最终的输出是以商品和服务表达的客户价值。
在生产力策略下，如果存在业务问题（结果），则缺陷（原因）必须在资源的质量/数量或流程故障范围内。同样，如果公司有增长战略，则必须扩大资源和/或系统流程。
您对这样的用例有何看法？]]></description>
      <guid>https://community.openai.com/t/extending-chatgpts-deductive-and-logical-reasoning-capabilities/569484?page=2#post_28</guid>
      <pubDate>Sat, 30 Dec 2023 15:05:46 GMT</pubDate>
    </item>
    <item>
      <title>打开 VPN 每次我问问题时我都必须证明我是人类？</title>
      <link>https://community.openai.com/t/with-vpn-on-every-time-i-ask-a-question-i-have-to-proof-that-i-am-human/576134#post_1</link>
      <description><![CDATA[打开 VPN 每次我问问题时我都必须证明我是人类？对于付费帐户来说这正常吗？我认为这是不正常的并且非常烦人。]]></description>
      <guid>https://community.openai.com/t/with-vpn-on-every-time-i-ask-a-question-i-have-to-proof-that-i-am-human/576134#post_1</guid>
      <pubDate>Sat, 30 Dec 2023 14:58:51 GMT</pubDate>
    </item>
    <item>
      <title>GPT 错误 - 用户报告 GPT 无法与 Action 对话</title>
      <link>https://community.openai.com/t/gpts-bug-user-reporting-gpt-cant-talk-to-action/527633#post_14</link>
      <description><![CDATA[问题似乎仍然存在。
创建了一个操作，它可以工作大约 10-15 个调用，之后它甚至没有向我的服务发出请求就失败了，真的令人沮丧，当询问出了什么问题时，我只得到 ClientResponseError 作为答案，而 GPT 可以甚至没有详细说明该错误。
从“询问”到“始终允许”来回切换有时可以修复它一段时间，也可以重新创建它修复它一段时间。
在它开始失败后，我也等了几个小时，看看这是否只是暂时的问题，但没有运气。
尝试创建具有某些自定义功能的 GPT 时确实很不方便。
在某些时候，我还会重新阅读服务条款，看看我是否违反了任何规定，他们可能只是阻止我，但没有任何迹象表明我有任何违规行为。
调用操作的频率是否有限制？
对于我的 GPT 想法，它需要经常与我的 API 以及那些有时对一个提示发出多达 15 个请求的 API 进行对话，具体取决于它的要求有多高。]]></description>
      <guid>https://community.openai.com/t/gpts-bug-user-reporting-gpt-cant-talk-to-action/527633#post_14</guid>
      <pubDate>Sat, 30 Dec 2023 14:56:24 GMT</pubDate>
    </item>
    <item>
      <title>EF 组织仅限于 1 级</title>
      <link>https://community.openai.com/t/ef-organization-restricted-to-tier-1/575940#post_3</link>
      <description><![CDATA[


饮食：
&lt;块引用&gt;
您的帖子已被社区标记。请查看您的消息。


我不会编辑我的帖子。太糟糕了！]]></description>
      <guid>https://community.openai.com/t/ef-organization-restricted-to-tier-1/575940#post_3</guid>
      <pubDate>Sat, 30 Dec 2023 14:54:52 GMT</pubDate>
    </item>
    <item>
      <title>在流式回答结束时遇到错误</title>
      <link>https://community.openai.com/t/stuck-on-getting-an-error-at-the-end-of-a-streamed-answer/576131#post_1</link>
      <description><![CDATA[我已经设置了流式传输，它似乎可以正常工作，只是我在流式传输结束时不断收到错误消息。完整的内容仍然显示在前端。也许这与流的关闭方式有关？即使尝试打印并记录所有内容后，我也无法弄清楚出了什么问题。这是我的代码和控制台的屏幕截图：
script.js
document.querySelector(&#39;.search-button&#39;).addEventListener(&#39;click&#39;, function(event) {
    event.preventDefault();
    var query = document.getElementById(&#39;searchQuery&#39;).value;

    // 清除现有内容
    var answerContainer = document.getElementById(&#39;answerContainer&#39;);
    answerContainer.innerHTML = &#39;&#39;;

    // 建立与服务器的连接以进行流式响应
    varstream=newEventSource(&#39;/search?query=&#39;+encodeURIComponent(query));

    // 监听流何时成功打开
    Stream.onopen = 函数(事件) {
      console.log(&#39;流打开成功：&#39;, event);
    };

    // 监听来自服务器的消息
    Stream.onmessage = 函数（事件）{
      answerContainer.textContent += event.data; // 追加每个数据块
    };

    流.onerror = 函数（错误）{
        console.error(&#39;流错误：&#39;, error);
        if (event.target &amp;&amp; event.target.readyState === EventSource.CLOSED) {
          console.log(&#39;流已关闭&#39;);
      }
        answerContainer.textContent += &#39;\n流中出现错误。&#39;;
        流.close(); // 出错时关闭流
    };
  });
});

搜索.py
# 来自 OpenAI 的流响应
    def 生成（）：
        尝试：
            流= openai_client.chat.completions.create(
                型号=“gpt-4-1106-预览”，
                消息=[
                    {&quot;role&quot;: &quot;system&quot;, &quot;content&quot;: &quot;这是一个测试。&quot;},
                    {“角色”：“用户”，“内容”：f“{上下文} {查询}”}
                ],
                流=真
            ）
            对于流中的块：
                if chunk.choices[0].delta.content:
                    产量 f&quot;数据: {chunk.choices[0].delta.content}\n\n&quot;
                    
        除了异常 e：
            error_info = traceback.format_exc()
            print(f&quot;发生错误：{e}&quot;)
            print(f&quot;流式传输期间发生错误：{error_info}&quot;)
            print(&quot;发生错误：&quot;,traceback.format_exc())
            产量 f“数据：错误：{str(e)}\n\n”

    返回响应（生成（），content_type =&#39;文本/事件流&#39;）

def extract_context(es_data):
    上下文=&#39;&#39;
    对于 es_data[&#39;hits&#39;][&#39;hits&#39;] 中的命中：
        Article_url = hit[&#39;_source&#39;].get(&#39;articleURL&#39;, &#39;&#39;)
        chunked_content = hit[&#39;_source&#39;].get(&#39;chunkedContent&#39;, &#39;&#39;)
        # 在命中之间添加分隔符
        context += f&quot;文章网址：{article_url}。摘录：{chunked_content}\n\n---\n\n&quot;
    返回上下文

如果 __name__ == &#39;__main__&#39;:
    应用程序运行（调试=真）

&lt; /p&gt;]]></description>
      <guid>https://community.openai.com/t/stuck-on-getting-an-error-at-the-end-of-a-streamed-answer/576131#post_1</guid>
      <pubDate>Sat, 30 Dec 2023 14:54:34 GMT</pubDate>
    </item>
    <item>
      <title>用于调用自定义函数的助手随机生成器参数值</title>
      <link>https://community.openai.com/t/assistant-randomly-generator-parameter-values-to-call-the-custom-function/575677#post_2</link>
      <description><![CDATA[如果没有提示，这也很难说。
也尝试不同的模型 - 他们会对不同的提示做出不同的反应。]]></description>
      <guid>https://community.openai.com/t/assistant-randomly-generator-parameter-values-to-call-the-custom-function/575677#post_2</guid>
      <pubDate>Sat, 30 Dec 2023 14:43:41 GMT</pubDate>
    </item>
    </channel>
</rss>